{
  "id": "CVE-2023-29824",
  "sourceIdentifier": "cve@mitre.org",
  "published": "2023-07-06T21:15:09.060",
  "lastModified": "2023-07-07T12:50:22.490",
  "vulnStatus": "Awaiting Analysis",
  "descriptions": [
    {
      "lang": "en",
      "value": "A use-after-free issue was discovered in Py_FindObjects() function in SciPy versions prior to 1.8.0."
    }
  ],
  "metrics": {},
  "references": [
    {
      "url": "http://www.square16.org/achievement/cve-2023-29824/",
      "source": "cve@mitre.org"
    },
    {
      "url": "https://github.com/scipy/scipy/issues/14713",
      "source": "cve@mitre.org"
    },
    {
      "url": "https://github.com/scipy/scipy/pull/15013",
      "source": "cve@mitre.org"
    }
  ]
}