{
  "id": "CVE-2022-48560",
  "sourceIdentifier": "cve@mitre.org",
  "published": "2023-08-22T19:16:31.827",
  "lastModified": "2023-08-22T19:16:31.827",
  "vulnStatus": "Received",
  "descriptions": [
    {
      "lang": "en",
      "value": "A use-after-free exists in Python through 3.9 via heappushpop in heapq."
    }
  ],
  "metrics": {},
  "references": [
    {
      "url": "https://bugs.python.org/issue39421",
      "source": "cve@mitre.org"
    }
  ]
}