{
  "id": "CVE-2022-48560",
  "sourceIdentifier": "cve@mitre.org",
  "published": "2023-08-22T19:16:31.827",
  "lastModified": "2023-09-20T22:15:11.670",
  "vulnStatus": "Modified",
  "descriptions": [
    {
      "lang": "en",
      "value": "A use-after-free exists in Python through 3.9 via heappushpop in heapq."
    }
  ],
  "metrics": {
    "cvssMetricV31": [
      {
        "source": "nvd@nist.gov",
        "type": "Primary",
        "cvssData": {
          "version": "3.1",
          "vectorString": "CVSS:3.1/AV:N/AC:L/PR:N/UI:N/S:U/C:N/I:N/A:H",
          "attackVector": "NETWORK",
          "attackComplexity": "LOW",
          "privilegesRequired": "NONE",
          "userInteraction": "NONE",
          "scope": "UNCHANGED",
          "confidentialityImpact": "NONE",
          "integrityImpact": "NONE",
          "availabilityImpact": "HIGH",
          "baseScore": 7.5,
          "baseSeverity": "HIGH"
        },
        "exploitabilityScore": 3.9,
        "impactScore": 3.6
      }
    ]
  },
  "weaknesses": [
    {
      "source": "nvd@nist.gov",
      "type": "Primary",
      "description": [
        {
          "lang": "en",
          "value": "CWE-416"
        }
      ]
    }
  ],
  "configurations": [
    {
      "nodes": [
        {
          "operator": "OR",
          "negate": false,
          "cpeMatch": [
            {
              "vulnerable": true,
              "criteria": "cpe:2.3:a:python:python:*:*:*:*:*:*:*:*",
              "versionStartIncluding": "3.7.0",
              "versionEndIncluding": "3.9.0",
              "matchCriteriaId": "FFF8C84C-9C4F-4D5A-BA22-1BD645F3D7AB"
            }
          ]
        }
      ]
    }
  ],
  "references": [
    {
      "url": "https://bugs.python.org/issue39421",
      "source": "cve@mitre.org",
      "tags": [
        "Exploit",
        "Issue Tracking",
        "Patch",
        "Vendor Advisory"
      ]
    },
    {
      "url": "https://lists.debian.org/debian-lts-announce/2023/09/msg00022.html",
      "source": "cve@mitre.org"
    }
  ]
}