{
  "id": "CVE-2022-48565",
  "sourceIdentifier": "cve@mitre.org",
  "published": "2023-08-22T19:16:32.007",
  "lastModified": "2023-09-01T13:36:41.637",
  "vulnStatus": "Analyzed",
  "descriptions": [
    {
      "lang": "en",
      "value": "An XML External Entity (XXE) issue was discovered in Python through 3.9.1. The plistlib module no longer accepts entity declarations in XML plist files to avoid XML vulnerabilities."
    }
  ],
  "metrics": {
    "cvssMetricV31": [
      {
        "source": "nvd@nist.gov",
        "type": "Primary",
        "cvssData": {
          "version": "3.1",
          "vectorString": "CVSS:3.1/AV:N/AC:L/PR:N/UI:N/S:U/C:H/I:H/A:H",
          "attackVector": "NETWORK",
          "attackComplexity": "LOW",
          "privilegesRequired": "NONE",
          "userInteraction": "NONE",
          "scope": "UNCHANGED",
          "confidentialityImpact": "HIGH",
          "integrityImpact": "HIGH",
          "availabilityImpact": "HIGH",
          "baseScore": 9.8,
          "baseSeverity": "CRITICAL"
        },
        "exploitabilityScore": 3.9,
        "impactScore": 5.9
      }
    ]
  },
  "weaknesses": [
    {
      "source": "nvd@nist.gov",
      "type": "Primary",
      "description": [
        {
          "lang": "en",
          "value": "CWE-611"
        }
      ]
    }
  ],
  "configurations": [
    {
      "nodes": [
        {
          "operator": "OR",
          "negate": false,
          "cpeMatch": [
            {
              "vulnerable": true,
              "criteria": "cpe:2.3:a:python:python:*:*:*:*:*:*:*:*",
              "versionStartIncluding": "3.6.0",
              "versionEndIncluding": "3.9.1",
              "matchCriteriaId": "B43C829B-7FDF-4D02-90BF-9EFE77EB8659"
            }
          ]
        }
      ]
    }
  ],
  "references": [
    {
      "url": "https://bugs.python.org/issue42051",
      "source": "cve@mitre.org",
      "tags": [
        "Exploit",
        "Issue Tracking",
        "Patch",
        "Vendor Advisory"
      ]
    }
  ]
}